Workbook

Sheet 25 portfolios Data
B1: SMALL LoBM | C1: ME1 BM2 | D1: ME1 BM3 | E1: ME1 BM4 | F1: SMALL HiBM | G1: ME2 BM1 | H1: ME2 BM2 | I1: ME2 BM3 | J1: ME2 BM4 | K1: ME2 BM5 | L1: ME3 BM1 | M1: ME3 BM2 | N1: ME3 BM3 | O1: ME3 BM4 | P1: ME3 BM5 | Q1: ME4 BM1 | R1: ME4 BM2 | S1: ME4 BM3 | T1: ME4 BM4 | U1: ME4 BM5 | V1: BIG LoBM | W1: ME5 BM2 | X1: ME5 BM3 | Y1: ME5 BM4 | Z1: BIG HiBM
A2: 200108 | B2: -5.67 | C2: -4.1 | D2: -2.06 | E2: -0.44 | F2: 0.72 | G2: -3.7 | H2: -5.19 | I2: -1.15 | J2: -0.8 | K2: 0.71 | L2: -4.46 | M2: -3.87 | N2: -2.46 | O2: -0.17 | P2: -0.06 | Q2: -6.35 | R2: -3.46 | S2: -2.2 | T2: -1.88 | U2: -0.21 | V2: -6.68 | W2: -4.67 | X2: -3.49 | Y2: -1.06 | Z2: -6.83
A3: 200109 | B3: -18.49 | C3: -17.39 | D3: -14.3 | E3: -12.9 | F3: -10.9 | G3: -19.12 | H3: -15.35 | I3: -13.42 | J3: -12.27 | K3: -11.87 | L3: -17.03 | M3: -14.18 | N3: -12.69 | O3: -11.89 | P3: -12.52 | Q3: -14.77 | R3: -12.52 | S3: -11.14 | T3: -10.77 | U3: -13.21 | V3: -6.03 | W3: -8.83 | X3: -11.46 | Y3: -10.26 | Z3: -9.74
A4: 200110 | B4: 8.77 | C4: 8.42 | D4: 5.93 | E4: 5.61 | F4: 3.59 | G4: 9.69 | H4: 8 | I4: 5.75 | J4: 4.15 | K4: 2.3 | L4: 12.38 | M4: 8.24 | N4: 5.23 | O4: 3.75 | P4: 2.23 | Q4: 9.3 | R4: 6.4 | S4: 2.51 | T4: 2.22 | U4: 2.33 | V4: 4.05 | W4: 1.93 | X4: 2.33 | Y4: 0.69 | Z4: -0.9
A5: 200111 | B5: 6.1 | C5: 6.52 | D5: 7.06 | E5: 4.33 | F5: 2.45 | G5: 5.04 | H5: 8.64 | I5: 4.36 | J5: 4.74 | K5: 3.66 | L5: 8.21 | M5: 6.24 | N5: 4.81 | O5: 4.14 | P5: 4.78 | Q5: 8.09 | R5: 6.71 | S5: 4.6 | T5: 4.26 | U5: 6.11 | V5: 6.75 | W5: 5.44 | X5: 4.53 | Y5: 4.98 | Z5: 8.53
A6: 200112 | B6: -0.96 | C6: 1.27 | D6: 0.59 | E6: 0.08 | F6: 0 | G6: 0.67 | H6: 3.1 | I6: 0.78 | J6: 2.13 | K6: 1.52 | L6: -0.07 | M6: 3.38 | N6: 2.59 | O6: 2.98 | P6: 1.45 | Q6: -0.24 | R6: 1.69 | S6: 2.26 | T6: 1.74 | U6: 2.65 | V6: -0.5 | W6: 0.69 | X6: 1.09 | Y6: 1.59 | Z6: 1.6
A7: 200201 | B7: -2.45 | C7: -3.06 | D7: -2.02 | E7: -0.52 | F7: 1.48 | G7: -5.81 | H7: -4.24 | I7: -3 | J7: -0.66 | K7: -0.29 | L7: -4.86 | M7: -3.08 | N7: -2.3 | O7: -1.48 | P7: 0.11 | Q7: -4.59 | R7: -3.43 | S7: -2.53 | T7: -0.08 | U7: -0.28 | V7: -2.87 | W7: -2.35 | X7: -3.98 | Y7: -1.75 | Z7: -7.09
A8: 200202 | B8: -4.26 | C8: -3.88 | D8: -2.48 | E8: -0.16 | F8: 1.24 | G8: -5 | H8: -3.73 | I8: -0.25 | J8: 0.08 | K8: 3.26 | L8: -3.86 | M8: -2.39 | N8: 0.63 | O8: 1.7 | P8: 2.55 | Q8: -3.7 | R8: 0.09 | S8: 1.53 | T8: 2.57 | U8: 1.5 | V8: -1.27 | W8: -0.58 | X8: 0.22 | Y8: 0 | Z8: -3.33
A9: 200203 | B9: 2.54 | C9: 4.47 | D9: 5.64 | E9: 4.71 | F9: 6.03 | G9: 4.98 | H9: 6.71 | I9: 6.89 | J9: 6.21 | K9: 6.24 | L9: 6.98 | M9: 6.78 | N9: 6.41 | O9: 6.04 | P9: 5.45 | Q9: 6.94 | R9: 5.42 | S9: 6.21 | T9: 5.56 | U9: 4.4 | V9: 2.44 | W9: 4.99 | X9: 6.48 | Y9: 4.86 | Z9: 4.61
A10: 200204 | B10: -3.81 | C10: -1.87 | D10: 1.01 | E10: 2.23 | F10: 4.6 | G10: -1.75 | H10: -0.73 | I10: 3.37 | J10: 3.82 | K10: 4.75 | L10: -4.67 | M10: 0.57 | N10: 2.65 | O10: 2.42 | P10: 3.43 | Q10: -4.18 | R10: 1.61 | S10: 1.64 | T10: 2.21 | U10: 1.57 | V10: -6.73 | W10: -3.86 | X10: -0.7 | Y10: 1.89 | Z10: -4.91
A11: 200205 | B11: -1.63 | C11: 0.79 | D11: 0.52 | E11: 3.81 | F11: 4.82 | G11: -0.33 | H11: -0.19 | I11: 0.91 | J11: 1.67 | K11: 1.9 | L11: -1.5 | M11: -0.56 | N11: 0.34 | O11: 0.77 | P11: 1.89 | Q11: -0.75 | R11: 0.41 | S11: 2.11 | T11: 2.53 | U11: 1.89 | V11: -2.04 | W11: 1.24 | X11: 0.61 | Y11: 1.43 | Z11: 1.03
A12: 200206 | B12: -6.55 | C12: -3.92 | D12: -3.51 | E12: -2.29 | F12: -0.43 | G12: -5.67 | H12: -4.6 | I12: -3.05 | J12: -1.95 | K12: -1.27 | L12: -7.61 | M12: -4.26 | N12: -4.9 | O12: -3.72 | P12: -3.23 | Q12: -7.05 | R12: -5.3 | S12: -5.31 | T12: -4.4 | U12: -3.87 | V12: -5.84 | W12: -5.61 | X12: -5.51 | Y12: -4.2 | Z12: -7.9
A13: 200207 | B13: -10.19 | C13: -11.4 | D13: -8.84 | E13: -8.77 | F13: -6.58 | G13: -10.75 | H13: -11.87 | I13: -10.45 | J13: -9.64 | K13: -9.48 | L13: -10.31 | M13: -9.8 | N13: -10.64 | O13: -9.77 | P13: -9.99 | Q13: -10.37 | R13: -9.92 | S13: -8.72 | T13: -7.77 | U13: -10.26 | V13: -6.01 | W13: -9.43 | X13: -10.03 | Y13: -8.71 | Z13: -9.14
... A291: 202509 | B291: 2.34 | C291: 1.37 | D291: 2.83 | E291: 3.64 | F291: 2.21 | G291: 1.04 | H291: -0.8 | I291: 1.76 | J291: 2.98 | K291: 2.28 | L291: -1.12 | M291: 2.75 | N291: 0.49 | O291: 1.39 | P291: 1.26 | Q291: -0.75 | R291: -0.01 | S291: 1.26 | T291: 0.84 | U291: 2.73 | V291: 5.93 | W291: 2.52 | X291: 0.73 | Y291: 2.69 | Z291: 1.76
A295: Average Equal Weighted Returns -- Monthly
B296: SMALL LoBM | C296: ME1 BM2 | D296: ME1 BM3 | E296: ME1 BM4 | F296: SMALL HiBM | G296: ME2 BM1 | H296: ME2 BM2 | I296: ME2 BM3 | J296: ME2 BM4 | K296: ME2 BM5 | L296: ME3 BM1 | M296: ME3 BM2 | N296: ME3 BM3 | O296: ME3 BM4 | P296: ME3 BM5 | Q296: ME4 BM1 | R296: ME4 BM2 | S296: ME4 BM3 | T296: ME4 BM4 | U296: ME4 BM5 | V296: BIG LoBM | W296: ME5 BM2 | X296: ME5 BM3 | Y296: ME5 BM4 | Z296: BIG HiBM
A297: 199007 | B297: 1.48 | C297: 1.86 | D297: 1.54 | E297: 2.29 | F297: 0.93 | G297: 1.72 | H297: 1.1 | I297: 2.13 | J297: 0.94 | K297: 0.9 | L297: 2.57 | M297: 2.78 | N297: 2.86 | O297: 3.04 | P297: 2.15 | Q297: 3.23 | R297: 3.04 | S297: 2.57 | T297: 2.46 | U297: 2.87 | V297: 2.45 | W297: 1.71 | X297: 1.87 | Y297: 2.51 | Z297: 1.78
A298: 199008 | B298: -8.88 | C298: -9.75 | D298: -8.39 | E298: -7.52 | F298: -7.17 | G298: -12.23 | H298: -10.38 | I298: -11.52 | J298: -11.3 | K298: -10.1 | L298: -13.87 | M298: -12.41 | N298: -13.11 | O298: -11.8 | P298: -11.77 | Q298: -11.69 | R298: -11.57 | S298: -11.75 | T298: -12.2 | U298: -12.28 | V298: -10.57 | W298: -10.75 | X298: -11.01 | Y298: -11.13 | Z298: -11.16
A299: 199009 | B299: -9.43 | C299: -8.47 | D299: -8.91 | E299: -6.8 | F299: -7.5 | G299: -11.05 | H299: -10.53 | I299: -9.67 | J299: -8.99 | K299: -9.26 | L299: -12.54 | M299: -11.57 | N299: -11.93 | O299: -11.96 | P299: -12.59 | Q299: -12.95 | R299: -11.33 | S299: -12.15 | T299: -12.88 | U299: -13.13 | V299: -12.37 | W299: -11.95 | X299: -11.76 | Y299: -12.97 | Z299: -13.54
A300: 199010 | B300: -1.5 | C300: -1.03 | D300: -0.47 | E300: -2.21 | F300: -4.03 | G300: 6.2 | H300: 1.27 | I300: 1.95 | J300: 1.84 | K300: 0.07 | L300: 11.84 | M300: 9.51 | N300: 8.15 | O300: 6.9 | P300: 6.37 | Q300: 12.38 | R300: 9.1 | S300: 11.13 | T300: 10.16 | U300: 9.41 | V300: 10.38 | W300: 13.79 | X300: 11.14 | Y300: 9.77 | Z300: 9.87
A301: 199011 | B301: 0.11 | C301: -1.24 | D301: -0.4 | E301: -0.53 | F301: -0.43 | G301: -0.93 | H301: 1.94 | I301: 0.22 | J301: 0.68 | K301: 0.86 | L301: -5.45 | M301: -2.23 | N301: -2.21 | O301: -4.57 | P301: -2.24 | Q301: -4.02 | R301: -3.83 | S301: -3.68 | T301: -4.77 | U301: -4.38 | V301: -1.86 | W301: -3.52 | X301: -2.76 | Y301: -1.61 | Z301: -2.6
A302: 199012 | B302: -1.94 | C302: 1.55 | D302: -0.07 | E302: -1.12 | F302: -0.54 | G302: 1.81 | H302: 1.45 | I302: 1.8 | J302: 2.04 | K302: 1.8 | L302: 2.54 | M302: 1.25 | N302: 0.4 | O302: -0.22 | P302: 0.43 | Q302: -0.02 | R302: 1.04 | S302: -0.2 | T302: 0.33 | U302: 0.85 | V302: 1.69 | W302: 1.25 | X302: 2.3 | Y302: 1.64 | Z302: 0.82
A303: 199101 | B303: 2.74 | C303: 2.65 | D303: 1.81 | E303: 1.54 | F303: 4.57 | G303: 0.15 | H303: 1.29 | I303: 1.9 | J303: 2.81 | K303: 2.61 | L303: -0.21 | M303: 0.26 | N303: 1.43 | O303: -0.82 | P303: 0.82 | Q303: 0.25 | R303: 1.71 | S303: 0.19 | T303: 0.74 | U303: 1.74 | V303: 3.53 | W303: 3.1 | X303: 2.6 | Y303: 2.94 | Z303: 4.79
A304: 199102 | B304: 12.53 | C304: 11.63 | D304: 10.24 | E304: 9.44 | F304: 10.76 | G304: 15.68 | H304: 13.52 | I304: 13.5 | J304: 10.82 | K304: 12.3 | L304: 16.25 | M304: 13.85 | N304: 14.91 | O304: 15.4 | P304: 14.94 | Q304: 15.35 | R304: 12.78 | S304: 14.2 | T304: 15.22 | U304: 14.68 | V304: 11.19 | W304: 10.64 | X304: 10.28 | Y304: 11.22 | Z304: 11.68
A305: 199103 | B305: 4.06 | C305: 2.8 | D305: 2.54 | E305: 2.5 | F305: 4.1 | G305: 1.47 | H305: 0.1 | I305: 0.22 | J305: 0.9 | K305: 1.1 | L305: -0.47 | M305: -0.73 | N305: -0.93 | O305: -1.89 | P305: 0.34 | Q305: -0.91 | R305: -2.16 | S305: -2.77 | T305: -1.71 | U305: -0.48 | V305: -2.84 | W305: -2.17 | X305: -2.68 | Y305: -2.51 | Z305: -2.65
A306: 199104 | B306: 1.12 | C306: 1.07 | D306: 1.15 | E306: 0.59 | F306: 2.3 | G306: 1.03 | H306: 1.34 | I306: 1.03 | J306: -0.23 | K306: 0.89 | L306: 0.41 | M306: 0.38 | N306: 0.05 | O306: 1.32 | P306: 1.16 | Q306: -0.15 | R306: -0.27 | S306: 0.84 | T306: 0.92 | U306: 1.08 | V306: 0.44 | W306: 1.25 | X306: 0.19 | Y306: 1.16 | Z306: 0.59
A307: 199105 | B307: 1.46 | C307: 0.11 | D307: -0.48 | E307: -1.14 | F307: 0.31 | G307: -0.91 | H307: 0.17 | I307: 1.17 | J307: 1.27 | K307: 0.22 | L307: -1 | M307: 0.24 | N307: 1 | O307: 0.91 | P307: 0.68 | Q307: -0.12 | R307: 0.27 | S307: -0.56 | T307: 1.21 | U307: 0.63 | V307: 1.59 | W307: 1.31 | X307: 2.01 | Y307: 1.54 | Z307: 1.88
A308: 199106 | B308: -4.88 | C308: -6.02 | D308: -4.11 | E308: -3.34 | F308: -3.13 | G308: -5.09 | H308: -5.45 | I308: -4.33 | J308: -4.4 | K308: -3.99 | L308: -5.79 | M308: -6.17 | N308: -5.29 | O308: -3.91 | P308: -5.1 | Q308: -5.67 | R308: -5.21 | S308: -5.6 | T308: -5.08 | U308: -4.97 | V308: -6.87 | W308: -6.1 | X308: -6.08 | Y308: -5.97 | Z308: -5.81
... A720: 202510 | B720: -1.34 | C720: -0.61 | D720: -0.35 | E720: -0.69 | F720: 0.09 | G720: -1.46 | H720: -0.2 | I720: 0.49 | J720: -0.47 | K720: -0.83 | L720: -1.99 | M720: -0.51 | N720: 0.1 | O720: -1.76 | P720: -0.94 | Q720: 0.6 | R720: 2.04 | S720: -0.02 | T720: -0.02 | U720: -1.06 | V720: 0.07 | W720: 0.94 | X720: -0.44 | Y720: 0.05 | Z720: -0.32
A724: Average Value Weighted Returns -- Annual
B725: SMALL LoBM | C725: ME1 BM2 | D725: ME1 BM3 | E725: ME1 BM4 | F725: SMALL HiBM | G725: ME2 BM1 | H725: ME2 BM2 | I725: ME2 BM3 | J725: ME2 BM4 | K725: ME2 BM5 | L725: ME3 BM1 | M725: ME3 BM2 | N725: ME3 BM3 | O725: ME3 BM4 | P725: ME3 BM5 | Q725: ME4 BM1 | R725: ME4 BM2 | S725: ME4 BM3 | T725: ME4 BM4 | U725: ME4 BM5 | V725: BIG LoBM | W725: ME5 BM2 | X725: ME5 BM3 | Y725: ME5 BM4 | Z725: BIG HiBM
A726: 1991 | B726: 29.21 | C726: 27.81 | D726: 26.32 | E726: 24.48 | F726: 24.9 | G726: 19.45 | H726: 23.27 | I726: 18.37 | J726: 16.81 | K726: 16.37 | L726: 19.68 | M726: 14.07 | N726: 15.86 | O726: 13.24 | P726: 18.09 | Q726: 17.87 | R726: 15.31 | S726: 7.87 | T726: 19.52 | U726: 18.34 | V726: 29.88 | W726: 14.55 | X726: 16.26 | Y726: 13.46 | Z726: 15.12
A727: 1992 | B727: -9.18 | C727: -4.31 | D727: 2.98 | E727: -1.94 | F727: 7.56 | G727: -13.39 | H727: -5.04 | I727: -4.08 | J727: -1.74 | K727: 2.43 | L727: -10.82 | M727: -7.42 | N727: -7.37 | O727: -6.78 | P727: -1.43 | Q727: -12.94 | R727: -4.23 | S727: -6.43 | T727: -4.83 | U727: -6.38 | V727: -7.17 | W727: -7.53 | X727: -5.61 | Y727: -5.1 | Z727: -2.02
A728: 1993 | B728: 21.55 | C728: 28.41 | D728: 35.91 | E728: 45.04 | F728: 49.63 | G728: 23.1 | H728: 27.01 | I728: 30.81 | J728: 33.62 | K728: 36.58 | L728: 18.07 | M728: 25 | N728: 24 | O728: 32.52 | P728: 37.45 | Q728: 15.38 | R728: 22.05 | S728: 26.95 | T728: 27.77 | U728: 33.37 | V728: 10.32 | W728: 18.14 | X728: 23.31 | Y728: 25.02 | Z728: 33.36
A729: 1994 | B729: -7.27 | C729: -1.57 | D729: 5.28 | E729: 2.88 | F729: 10.91 | G729: 0.4 | H729: -2.81 | I729: 5.27 | J729: 8.95 | K729: 13.13 | L729: 7.85 | M729: 5.82 | N729: 8.23 | O729: 9.95 | P729: 10.54 | Q729: 2.81 | R729: 3.57 | S729: 6.92 | T729: 6.54 | U729: 9.1 | V729: 1.67 | W729: 6.93 | X729: 7.52 | Y729: 5.3 | Z729: 9.91
A730: 1995 | B730: 25.83 | C730: 21.97 | D730: 23.28 | E730: 14.67 | F730: 19.8 | G730: 17.25 | H730: 18.61 | I730: 16.35 | J730: 15.06 | K730: 13.99 | L730: 15.29 | M730: 10.27 | N730: 6.79 | O730: 11.16 | P730: 9.32 | Q730: 26.1 | R730: 12.32 | S730: 12 | T730: 12.03 | U730: 10.79 | V730: 20.66 | W730: 20.58 | X730: 17.67 | Y730: 19.27 | Z730: 22.88
A731: 1996 | B731: 5.01 | C731: 14.3 | D731: 14.13 | E731: 20.79 | F731: 21.61 | G731: 2.96 | H731: 8.5 | I731: 10.25 | J731: 14.82 | K731: 10.68 | L731: 2.75 | M731: 6.57 | N731: 10.17 | O731: 8.87 | P731: 9.54 | Q731: 6.23 | R731: 9.15 | S731: 7.63 | T731: 12 | U731: 13.02 | V731: 9.06 | W731: 11.91 | X731: 15.51 | Y731: 17.71 | Z731: 17.15
A732: 1997 | B732: -13.23 | C732: -5.98 | D732: -2.31 | E732: 3.48 | F732: 8.52 | G732: -11.92 | H732: -6.31 | I732: 0.45 | J732: 4.46 | K732: -4.49 | L732: -6.03 | M732: -2.66 | N732: 2.61 | O732: 5.17 | P732: 5.86 | Q732: -5.3 | R732: 0.5 | S732: 2.72 | T732: 7.84 | U732: 4.82 | V732: 19.47 | W732: 15.96 | X732: 14.41 | Y732: 19.83 | Z732: 23.73
A733: 1998 | B733: -2.08 | C733: -0.97 | D733: -3.28 | E733: -1.55 | F733: 3.7 | G733: 8.43 | H733: -0.75 | I733: 0.26 | J733: -0.31 | K733: 6.53 | L733: 8.85 | M733: 1.9 | N733: 5.56 | O733: 5.05 | P733: 10.18 | Q733: 17.97 | R733: 12.56 | S733: 5.9 | T733: 4.35 | U733: 9.77 | V733: 36.18 | W733: 21.77 | X733: 13.34 | Y733: 18.92 | Z733: 17.73
A734: 1999 | B734: 76.55 | C734: 56.3 | D734: 65.92 | E734: 39.17 | F734: 37.74 | G734: 62.07 | H734: 45.11 | I734: 26.59 | J734: 18.78 | K734: 15.31 | L734: 60.14 | M734: 38.59 | N734: 27.36 | O734: 3.59 | P734: 14.16 | Q734: 79.15 | R734: 18.01 | S734: 13.84 | T734: 8.07 | U734: 16.61 | V734: 40.41 | W734: 24.76 | X734: 27.43 | Y734: 10.05 | Z734: 14.42
...

Sheet Returns Data
B1: SMALL LoBM | C1: ME1 BM2 | D1: ME1 BM3 | E1: ME1 BM4 | F1: SMALL HiBM | G1: ME2 BM1 | H1: ME2 BM2 | I1: ME2 BM3 | J1: ME2 BM4 | K1: ME2 BM5 | L1: ME3 BM1 | M1: ME3 BM2 | N1: ME3 BM3 | O1: ME3 BM4 | P1: ME3 BM5 | Q1: ME4 BM1 | R1: ME4 BM2 | S1: ME4 BM3 | T1: ME4 BM4 | U1: ME4 BM5 | V1: BIG LoBM | W1: ME5 BM2 | X1: ME5 BM3 | Y1: ME5 BM4 | Z1: BIG HiBM
A2: 200108 | B2: ='25 portfolios Data'!B2/100 -> -0.0567 | C2: ='25 portfolios Data'!C2/100 -> -0.041 | D2: ='25 portfolios Data'!D2/100 -> -0.0206 | E2: ='25 portfolios Data'!E2/100 -> -0.0044 | F2: ='25 portfolios Data'!F2/100 -> 0.0072 | G2: ='25 portfolios Data'!G2/100 -> -0.037 | H2: ='25 portfolios Data'!H2/100 -> -0.0519 | I2: ='25 portfolios Data'!I2/100 -> -0.0115 | ... Z2: ='25 portfolios Data'!Z2/100 -> -0.0683
A3: 200109 | B3: ='25 portfolios Data'!B3/100 -> -0.1849 | C3: ='25 portfolios Data'!C3/100 -> -0.1739 | D3: ='25 portfolios Data'!D3/100 -> -0.143 | E3: ='25 portfolios Data'!E3/100 -> -0.129 | F3: ='25 portfolios Data'!F3/100 -> -0.109 | G3: ='25 portfolios Data'!G3/100 -> -0.1912 | H3: ='25 portfolios Data'!H3/100 -> -0.1535 | I3: ='25 portfolios Data'!I3/100 -> -0.1342 | ... Z3: ='25 portfolios Data'!Z3/100 -> -0.0974
A4: 200110 | B4: ='25 portfolios Data'!B4/100 -> 0.0877 | C4: ='25 portfolios Data'!C4/100 -> 0.0842 | D4: ='25 portfolios Data'!D4/100 -> 0.0593 | E4: ='25 portfolios Data'!E4/100 -> 0.0561 | F4: ='25 portfolios Data'!F4/100 -> 0.0359 | G4: ='25 portfolios Data'!G4/100 -> 0.0969 | H4: ='25 portfolios Data'!H4/100 -> 0.08 | I4: ='25 portfolios Data'!I4/100 -> 0.0575 | ... Z4: ='25 portfolios Data'!Z4/100 -> -0.009
A5: 200111 | B5: ='25 portfolios Data'!B5/100 -> 0.061 | C5: ='25 portfolios Data'!C5/100 -> 0.0652 | D5: ='25 portfolios Data'!D5/100 -> 0.0706 | E5: ='25 portfolios Data'!E5/100 -> 0.0433 | F5: ='25 portfolios Data'!F5/100 -> 0.0245 | G5: ='25 portfolios Data'!G5/100 -> 0.0504 | H5: ='25 portfolios Data'!H5/100 -> 0.0864 | I5: ='25 portfolios Data'!I5/100 -> 0.0436 | ... Z5: ='25 portfolios Data'!Z5/100 -> 0.0853
A6: 200112 | B6: ='25 portfolios Data'!B6/100 -> -0.0096 | C6: ='25 portfolios Data'!C6/100 -> 0.0127 | D6: ='25 portfolios Data'!D6/100 -> 0.0059 | E6: ='25 portfolios Data'!E6/100 -> 0.0008 | F6: ='25 portfolios Data'!F6/100 -> 0 | G6: ='25 portfolios Data'!G6/100 -> 0.0067 | H6: ='25 portfolios Data'!H6/100 -> 0.031 | I6: ='25 portfolios Data'!I6/100 -> 0.0078 | ... Z6: ='25 portfolios Data'!Z6/100 -> 0.016
A7: 200201 | B7: ='25 portfolios Data'!B7/100 -> -0.0245 | C7: ='25 portfolios Data'!C7/100 -> -0.0306 | D7: ='25 portfolios Data'!D7/100 -> -0.0202 | E7: ='25 portfolios Data'!E7/100 -> -0.0052 | F7: ='25 portfolios Data'!F7/100 -> 0.0148 | G7: ='25 portfolios Data'!G7/100 -> -0.0581 | H7: ='25 portfolios Data'!H7/100 -> -0.0424 | I7: ='25 portfolios Data'!I7/100 -> -0.03 | ... Z7: ='25 portfolios Data'!Z7/100 -> -0.0709
A8: 200202 | B8: ='25 portfolios Data'!B8/100 -> -0.0426 | C8: ='25 portfolios Data'!C8/100 -> -0.0388 | D8: ='25 portfolios Data'!D8/100 -> -0.0248 | E8: ='25 portfolios Data'!E8/100 -> -0.0016 | F8: ='25 portfolios Data'!F8/100 -> 0.0124 | G8: ='25 portfolios Data'!G8/100 -> -0.05 | H8: ='25 portfolios Data'!H8/100 -> -0.0373 | I8: ='25 portfolios Data'!I8/100 -> -0.0025 | ... Z8: ='25 portfolios Data'!Z8/100 -> -0.0333
A9: 200203 | B9: ='25 portfolios Data'!B9/100 -> 0.0254 | C9: ='25 portfolios Data'!C9/100 -> 0.0447 | D9: ='25 portfolios Data'!D9/100 -> 0.0564 | E9: ='25 portfolios Data'!E9/100 -> 0.0471 | F9: ='25 portfolios Data'!F9/100 -> 0.0603 | G9: ='25 portfolios Data'!G9/100 -> 0.0498 | H9: ='25 portfolios Data'!H9/100 -> 0.0671 | I9: ='25 portfolios Data'!I9/100 -> 0.0689 | ... Z9: ='25 portfolios Data'!Z9/100 -> 0.0461
A10: 200204 | B10: ='25 portfolios Data'!B10/100 -> -0.0381 | C10: ='25 portfolios Data'!C10/100 -> -0.0187 | D10: ='25 portfolios Data'!D10/100 -> 0.0101 | E10: ='25 portfolios Data'!E10/100 -> 0.0223 | F10: ='25 portfolios Data'!F10/100 -> 0.046 | G10: ='25 portfolios Data'!G10/100 -> -0.0175 | H10: ='25 portfolios Data'!H10/100 -> -0.0073 | I10: ='25 portfolios Data'!I10/100 -> 0.0337 | ... Z10: ='25 portfolios Data'!Z10/100 -> -0.0491
A11: 200205 | B11: ='25 portfolios Data'!B11/100 -> -0.0163 | C11: ='25 portfolios Data'!C11/100 -> 0.0079 | D11: ='25 portfolios Data'!D11/100 -> 0.0052 | E11: ='25 portfolios Data'!E11/100 -> 0.0381 | F11: ='25 portfolios Data'!F11/100 -> 0.0482 | G11: ='25 portfolios Data'!G11/100 -> -0.0033 | H11: ='25 portfolios Data'!H11/100 -> -0.0019 | I11: ='25 portfolios Data'!I11/100 -> 0.0091 | ... Z11: ='25 portfolios Data'!Z11/100 -> 0.0103
A12: 200206 | B12: ='25 portfolios Data'!B12/100 -> -0.0655 | C12: ='25 portfolios Data'!C12/100 -> -0.0392 | D12: ='25 portfolios Data'!D12/100 -> -0.0351 | E12: ='25 portfolios Data'!E12/100 -> -0.0229 | F12: ='25 portfolios Data'!F12/100 -> -0.0043 | G12: ='25 portfolios Data'!G12/100 -> -0.0567 | H12: ='25 portfolios Data'!H12/100 -> -0.046 | I12: ='25 portfolios Data'!I12/100 -> -0.0305 | ... Z12: ='25 portfolios Data'!Z12/100 -> -0.079
A13: 200207 | B13: ='25 portfolios Data'!B13/100 -> -0.1019 | C13: ='25 portfolios Data'!C13/100 -> -0.114 | D13: ='25 portfolios Data'!D13/100 -> -0.0884 | E13: ='25 portfolios Data'!E13/100 -> -0.0877 | F13: ='25 portfolios Data'!F13/100 -> -0.0658 | G13: ='25 portfolios Data'!G13/100 -> -0.1075 | H13: ='25 portfolios Data'!H13/100 -> -0.1187 | I13: ='25 portfolios Data'!I13/100 -> -0.1045 | ... Z13: ='25 portfolios Data'!Z13/100 -> -0.0914
... A291: 202509 | B291: ='25 portfolios Data'!B291/100 -> 0.0234 | C291: ='25 portfolios Data'!C291/100 -> 0.0137 | D291: ='25 portfolios Data'!D291/100 -> 0.0283 | E291: ='25 portfolios Data'!E291/100 -> 0.0364 | F291: ='25 portfolios Data'!F291/100 -> 0.0221 | G291: ='25 portfolios Data'!G291/100 -> 0.0104 | H291: ='25 portfolios Data'!H291/100 -> -0.008 | I291: ='25 portfolios Data'!I291/100 -> 0.0176 | ... Z291: ='25 portfolios Data'!Z291/100 -> 0.0176

Sheet Rf Rate
B1: Monthly Risk Free
A2: 200108 | B2: 0.0027901165
A3: 200109 | B3: 0.0018804295
A4: 200110 | B4: 0.0017742501
A5: 200111 | B5: 0.0015451345
A6: 200112 | B6: 0.0013893343
A7: 200201 | B7: 0.001397541
A8: 200202 | B8: 0.0014549669
A9: 200203 | B9: 0.0014549669
A10: 200204 | B10: 0.0014631677
A11: 200205 | B11: 0.0014221565
A12: 200206 | B12: 0.001397541
A13: 200207 | B13: 0.0014303602
... A291: 202509 | B291: 0.0034343793

Sheet Excess Returns Data
B1: SMALL LoBM | C1: ME1 BM2 | D1: ME1 BM3 | E1: ME1 BM4 | F1: SMALL HiBM | G1: ME2 BM1 | H1: ME2 BM2 | I1: ME2 BM3 | J1: ME2 BM4 | K1: ME2 BM5 | L1: ME3 BM1 | M1: ME3 BM2 | N1: ME3 BM3 | O1: ME3 BM4 | P1: ME3 BM5 | Q1: ME4 BM1 | R1: ME4 BM2 | S1: ME4 BM3 | T1: ME4 BM4 | U1: ME4 BM5 | V1: BIG LoBM | W1: ME5 BM2 | X1: ME5 BM3 | Y1: ME5 BM4 | Z1: BIG HiBM
A2: 200108 | B2: =('25 portfolios Data'!B2/100)-'Rf Rate'!$B2 -> -0.059490116 | C2: =('25 portfolios Data'!C2/100)-'Rf Rate'!$B2 -> -0.043790116 | D2: =('25 portfolios Data'!D2/100)-'Rf Rate'!$B2 -> -0.023390116 | E2: =('25 portfolios Data'!E2/100)-'Rf Rate'!$B2 -> -0.0071901165 | F2: =('25 portfolios Data'!F2/100)-'Rf Rate'!$B2 -> 0.0044098835 | G2: =('25 portfolios Data'!G2/100)-'Rf Rate'!$B2 -> -0.039790116 | H2: =('25 portfolios Data'!H2/100)-'Rf Rate'!$B2 -> -0.054690116 | I2: =('25 portfolios Data'!I2/100)-'Rf Rate'!$B2 -> -0.014290116 | ... Z2: =('25 portfolios Data'!Z2/100)-'Rf Rate'!$B2 -> -0.071090116
A3: 200109 | B3: =('25 portfolios Data'!B3/100)-'Rf Rate'!$B3 -> -0.18678043 | C3: =('25 portfolios Data'!C3/100)-'Rf Rate'!$B3 -> -0.17578043 | D3: =('25 portfolios Data'!D3/100)-'Rf Rate'!$B3 -> -0.14488043 | E3: =('25 portfolios Data'!E3/100)-'Rf Rate'!$B3 -> -0.13088043 | F3: =('25 portfolios Data'!F3/100)-'Rf Rate'!$B3 -> -0.11088043 | G3: =('25 portfolios Data'!G3/100)-'Rf Rate'!$B3 -> -0.19308043 | H3: =('25 portfolios Data'!H3/100)-'Rf Rate'!$B3 -> -0.15538043 | I3: =('25 portfolios Data'!I3/100)-'Rf Rate'!$B3 -> -0.13608043 | ... Z3: =('25 portfolios Data'!Z3/100)-'Rf Rate'!$B3 -> -0.099280429
A4: 200110 | B4: =('25 portfolios Data'!B4/100)-'Rf Rate'!$B4 -> 0.08592575 | C4: =('25 portfolios Data'!C4/100)-'Rf Rate'!$B4 -> 0.08242575 | D4: =('25 portfolios Data'!D4/100)-'Rf Rate'!$B4 -> 0.05752575 | E4: =('25 portfolios Data'!E4/100)-'Rf Rate'!$B4 -> 0.05432575 | F4: =('25 portfolios Data'!F4/100)-'Rf Rate'!$B4 -> 0.03412575 | G4: =('25 portfolios Data'!G4/100)-'Rf Rate'!$B4 -> 0.09512575 | H4: =('25 portfolios Data'!H4/100)-'Rf Rate'!$B4 -> 0.07822575 | I4: =('25 portfolios Data'!I4/100)-'Rf Rate'!$B4 -> 0.05572575 | ... Z4: =('25 portfolios Data'!Z4/100)-'Rf Rate'!$B4 -> -0.01077425
A5: 200111 | B5: =('25 portfolios Data'!B5/100)-'Rf Rate'!$B5 -> 0.059454865 | C5: =('25 portfolios Data'!C5/100)-'Rf Rate'!$B5 -> 0.063654865 | D5: =('25 portfolios Data'!D5/100)-'Rf Rate'!$B5 -> 0.069054865 | E5: =('25 portfolios Data'!E5/100)-'Rf Rate'!$B5 -> 0.041754865 | F5: =('25 portfolios Data'!F5/100)-'Rf Rate'!$B5 -> 0.022954865 | G5: =('25 portfolios Data'!G5/100)-'Rf Rate'!$B5 -> 0.048854865 | H5: =('25 portfolios Data'!H5/100)-'Rf Rate'!$B5 -> 0.084854865 | I5: =('25 portfolios Data'!I5/100)-'Rf Rate'!$B5 -> 0.042054865 | ... Z5: =('25 portfolios Data'!Z5/100)-'Rf Rate'!$B5 -> 0.083754865
A6: 200112 | B6: =('25 portfolios Data'!B6/100)-'Rf Rate'!$B6 -> -0.010989334 | C6: =('25 portfolios Data'!C6/100)-'Rf Rate'!$B6 -> 0.011310666 | D6: =('25 portfolios Data'!D6/100)-'Rf Rate'!$B6 -> 0.0045106657 | E6: =('25 portfolios Data'!E6/100)-'Rf Rate'!$B6 -> -0.00058933431 | F6: =('25 portfolios Data'!F6/100)-'Rf Rate'!$B6 -> -0.0013893343 | G6: =('25 portfolios Data'!G6/100)-'Rf Rate'!$B6 -> 0.0053106657 | H6: =('25 portfolios Data'!H6/100)-'Rf Rate'!$B6 -> 0.029610666 | I6: =('25 portfolios Data'!I6/100)-'Rf Rate'!$B6 -> 0.0064106657 | ... Z6: =('25 portfolios Data'!Z6/100)-'Rf Rate'!$B6 -> 0.014610666
A7: 200201 | B7: =('25 portfolios Data'!B7/100)-'Rf Rate'!$B7 -> -0.025897541 | C7: =('25 portfolios Data'!C7/100)-'Rf Rate'!$B7 -> -0.031997541 | D7: =('25 portfolios Data'!D7/100)-'Rf Rate'!$B7 -> -0.021597541 | E7: =('25 portfolios Data'!E7/100)-'Rf Rate'!$B7 -> -0.006597541 | F7: =('25 portfolios Data'!F7/100)-'Rf Rate'!$B7 -> 0.013402459 | G7: =('25 portfolios Data'!G7/100)-'Rf Rate'!$B7 -> -0.059497541 | H7: =('25 portfolios Data'!H7/100)-'Rf Rate'!$B7 -> -0.043797541 | I7: =('25 portfolios Data'!I7/100)-'Rf Rate'!$B7 -> -0.031397541 | ... Z7: =('25 portfolios Data'!Z7/100)-'Rf Rate'!$B7 -> -0.072297541
A8: 200202 | B8: =('25 portfolios Data'!B8/100)-'Rf Rate'!$B8 -> -0.044054967 | C8: =('25 portfolios Data'!C8/100)-'Rf Rate'!$B8 -> -0.040254967 | D8: =('25 portfolios Data'!D8/100)-'Rf Rate'!$B8 -> -0.026254967 | E8: =('25 portfolios Data'!E8/100)-'Rf Rate'!$B8 -> -0.0030549669 | F8: =('25 portfolios Data'!F8/100)-'Rf Rate'!$B8 -> 0.010945033 | G8: =('25 portfolios Data'!G8/100)-'Rf Rate'!$B8 -> -0.051454967 | H8: =('25 portfolios Data'!H8/100)-'Rf Rate'!$B8 -> -0.038754967 | I8: =('25 portfolios Data'!I8/100)-'Rf Rate'!$B8 -> -0.0039549669 | ... Z8: =('25 portfolios Data'!Z8/100)-'Rf Rate'!$B8 -> -0.034754967
A9: 200203 | B9: =('25 portfolios Data'!B9/100)-'Rf Rate'!$B9 -> 0.023945033 | C9: =('25 portfolios Data'!C9/100)-'Rf Rate'!$B9 -> 0.043245033 | D9: =('25 portfolios Data'!D9/100)-'Rf Rate'!$B9 -> 0.054945033 | E9: =('25 portfolios Data'!E9/100)-'Rf Rate'!$B9 -> 0.045645033 | F9: =('25 portfolios Data'!F9/100)-'Rf Rate'!$B9 -> 0.058845033 | G9: =('25 portfolios Data'!G9/100)-'Rf Rate'!$B9 -> 0.048345033 | H9: =('25 portfolios Data'!H9/100)-'Rf Rate'!$B9 -> 0.065645033 | I9: =('25 portfolios Data'!I9/100)-'Rf Rate'!$B9 -> 0.067445033 | ... Z9: =('25 portfolios Data'!Z9/100)-'Rf Rate'!$B9 -> 0.044645033
A10: 200204 | B10: =('25 portfolios Data'!B10/100)-'Rf Rate'!$B10 -> -0.039563168 | C10: =('25 portfolios Data'!C10/100)-'Rf Rate'!$B10 -> -0.020163168 | D10: =('25 portfolios Data'!D10/100)-'Rf Rate'!$B10 -> 0.0086368323 | E10: =('25 portfolios Data'!E10/100)-'Rf Rate'!$B10 -> 0.020836832 | F10: =('25 portfolios Data'!F10/100)-'Rf Rate'!$B10 -> 0.044536832 | G10: =('25 portfolios Data'!G10/100)-'Rf Rate'!$B10 -> -0.018963168 | H10: =('25 portfolios Data'!H10/100)-'Rf Rate'!$B10 -> -0.0087631677 | I10: =('25 portfolios Data'!I10/100)-'Rf Rate'!$B10 -> 0.032236832 | ... Z10: =('25 portfolios Data'!Z10/100)-'Rf Rate'!$B10 -> -0.050563168
A11: 200205 | B11: =('25 portfolios Data'!B11/100)-'Rf Rate'!$B11 -> -0.017722157 | C11: =('25 portfolios Data'!C11/100)-'Rf Rate'!$B11 -> 0.0064778435 | D11: =('25 portfolios Data'!D11/100)-'Rf Rate'!$B11 -> 0.0037778435 | E11: =('25 portfolios Data'!E11/100)-'Rf Rate'!$B11 -> 0.036677843 | F11: =('25 portfolios Data'!F11/100)-'Rf Rate'!$B11 -> 0.046777843 | G11: =('25 portfolios Data'!G11/100)-'Rf Rate'!$B11 -> -0.0047221565 | H11: =('25 portfolios Data'!H11/100)-'Rf Rate'!$B11 -> -0.0033221565 | I11: =('25 portfolios Data'!I11/100)-'Rf Rate'!$B11 -> 0.0076778435 | ... Z11: =('25 portfolios Data'!Z11/100)-'Rf Rate'!$B11 -> 0.0088778435
A12: 200206 | B12: =('25 portfolios Data'!B12/100)-'Rf Rate'!$B12 -> -0.066897541 | C12: =('25 portfolios Data'!C12/100)-'Rf Rate'!$B12 -> -0.040597541 | D12: =('25 portfolios Data'!D12/100)-'Rf Rate'!$B12 -> -0.036497541 | E12: =('25 portfolios Data'!E12/100)-'Rf Rate'!$B12 -> -0.024297541 | F12: =('25 portfolios Data'!F12/100)-'Rf Rate'!$B12 -> -0.005697541 | G12: =('25 portfolios Data'!G12/100)-'Rf Rate'!$B12 -> -0.058097541 | H12: =('25 portfolios Data'!H12/100)-'Rf Rate'!$B12 -> -0.047397541 | I12: =('25 portfolios Data'!I12/100)-'Rf Rate'!$B12 -> -0.031897541 | ... Z12: =('25 portfolios Data'!Z12/100)-'Rf Rate'!$B12 -> -0.080397541
A13: 200207 | B13: =('25 portfolios Data'!B13/100)-'Rf Rate'!$B13 -> -0.10333036 | C13: =('25 portfolios Data'!C13/100)-'Rf Rate'!$B13 -> -0.11543036 | D13: =('25 portfolios Data'!D13/100)-'Rf Rate'!$B13 -> -0.08983036 | E13: =('25 portfolios Data'!E13/100)-'Rf Rate'!$B13 -> -0.08913036 | F13: =('25 portfolios Data'!F13/100)-'Rf Rate'!$B13 -> -0.06723036 | G13: =('25 portfolios Data'!G13/100)-'Rf Rate'!$B13 -> -0.10893036 | H13: =('25 portfolios Data'!H13/100)-'Rf Rate'!$B13 -> -0.12013036 | I13: =('25 portfolios Data'!I13/100)-'Rf Rate'!$B13 -> -0.10593036 | ... Z13: =('25 portfolios Data'!Z13/100)-'Rf Rate'!$B13 -> -0.09283036
... A291: 202509 | B291: =('25 portfolios Data'!B291/100)-'Rf Rate'!$B291 -> 0.019965621 | C291: =('25 portfolios Data'!C291/100)-'Rf Rate'!$B291 -> 0.010265621 | D291: =('25 portfolios Data'!D291/100)-'Rf Rate'!$B291 -> 0.024865621 | E291: =('25 portfolios Data'!E291/100)-'Rf Rate'!$B291 -> 0.032965621 | F291: =('25 portfolios Data'!F291/100)-'Rf Rate'!$B291 -> 0.018665621 | G291: =('25 portfolios Data'!G291/100)-'Rf Rate'!$B291 -> 0.0069656207 | H291: =('25 portfolios Data'!H291/100)-'Rf Rate'!$B291 -> -0.011434379 | I291: =('25 portfolios Data'!I291/100)-'Rf Rate'!$B291 -> 0.014165621 | ... Z291: =('25 portfolios Data'!Z291/100)-'Rf Rate'!$B291 -> 0.014165621
